Error occurred while making a POST request to https://apiconnect.angelbroking.com/rest/secure/angelbroking/order/v1/getLtpData. Headers: {'Content-type': 'application/json', 'X-ClientLocalIP': '127.0.0.1', 'X-ClientPublicIP': '106.193.147.98', 'X-MACAddress': '6e:2c:8a:e7:f8:88', 'Accept': 'application/json', 'X-PrivateKey': 'gtpUuIED', 'X-UserType': 'USER', 'X-SourceID': 'WEB', 'Authorization': 'Bearer eyJhbGciOiJIUzUxMiJ9.eyJ1c2VybmFtZSI6IlA2NjkzMDAiLCJyb2xlcyI6MCwidXNlcnR5cGUiOiJVU0VSIiwidG9rZW4iOiJleUpoYkdjaU9pSklVelV4TWlJc0luUjVjQ0k2SWtwWFZDSjkuZXlKemRXSWlPaUpRTmpZNU16QXdJaXdpWlhod0lqb3hOekUyT1RVM01ERTNMQ0pwWVhRaU9qRTNNVFk0Tmprd05USXNJbXAwYVNJNklqWXlOR1ZrWTJNNUxUZG1NakV0TkRSbU5TMWhZbVpoTFRjd016TTVOamRpTm1ZeFppSXNJbTl0Ym1WdFlXNWhaMlZ5YVdRaU9qWXNJbk52ZFhKalpXbGtJam9pTXlJc0luVnpaWEpmZEhsd1pTSTZJbU5zYVdWdWRDSXNJblJ2YTJWdVgzUjVjR1VpT2lKMGNtRmtaVjloWTJObGMzTmZkRzlyWlc0aUxDSm5iVjlwWkNJNk5pd2ljMjkxY21ObElqb2lNeUlzSW1SbGRtbGpaVjlwWkNJNklqZzRZekZqTXpNNExUQXdaak10TXpRMll5MDVabVE1TFRneE5UUTVPR1ZpT1dJM1pTSXNJbUZqZENJNmUzMTkuT2dodWZ6eFFCaHZlWDV5cFpBeXJETUx0WFNNWW9tOEQ0UEhkVWdBTnFmNGhHUlF5aUhISm9CUXBzSXZCU2M2ZU1jX0dkWkNMQXVLTXRSRlF5bGp6bGciLCJBUEktS0VZIjoiZ3RwVXVJRUQiLCJpYXQiOjE3MTY4NjkxMTUsImV4cCI6MTcxNjk1NzAxN30.g4hbqsHdcDJtsecXF8zsG-JeZ0O3GskBRpCDM3zBzNwhunJDsuB5WT0HFNGH1r7bh6Yeq6lrZ_m964DsPRONyQ'}, Request: {'exchange': 'NFO', 'tradingsymbol': 'BANKNIFTY29MAY2449000PE', 'symboltoken': '56658'}, Response: HTTPSConnectionPool(host='apiconnect.angelbroking.com', port=443): Read timed out. (read timeout=7)
Traceback (most recent call last):
  File "/opt/homebrew/lib/python3.11/site-packages/urllib3/connectionpool.py", line 467, in _make_request
    six.raise_from(e, None)
  File "<string>", line 3, in raise_from
  File "/opt/homebrew/lib/python3.11/site-packages/urllib3/connectionpool.py", line 462, in _make_request
    httplib_response = conn.getresponse()